[2025-03-20T12:35:12.086+0000] {taskinstance.py:1087} INFO - Dependencies all met for <TaskInstance: tech_sentiment_pipeline.send_alert scheduled__2025-03-20T12:20:00+00:00 [queued]>
[2025-03-20T12:35:12.098+0000] {taskinstance.py:1087} INFO - Dependencies all met for <TaskInstance: tech_sentiment_pipeline.send_alert scheduled__2025-03-20T12:20:00+00:00 [queued]>
[2025-03-20T12:35:12.098+0000] {taskinstance.py:1283} INFO - 
--------------------------------------------------------------------------------
[2025-03-20T12:35:12.098+0000] {taskinstance.py:1284} INFO - Starting attempt 2 of 2
[2025-03-20T12:35:12.099+0000] {taskinstance.py:1285} INFO - 
--------------------------------------------------------------------------------
[2025-03-20T12:35:12.119+0000] {taskinstance.py:1304} INFO - Executing <Task(EmailOperator): send_alert> on 2025-03-20 12:20:00+00:00
[2025-03-20T12:35:12.125+0000] {standard_task_runner.py:55} INFO - Started process 339 to run task
[2025-03-20T12:35:12.129+0000] {standard_task_runner.py:82} INFO - Running: ['***', 'tasks', 'run', 'tech_sentiment_pipeline', 'send_alert', 'scheduled__2025-03-20T12:20:00+00:00', '--job-id', '13', '--raw', '--subdir', 'DAGS_FOLDER/sentiment_ETL_pipeline.py', '--cfg-path', '/tmp/tmpdbihed5k']
[2025-03-20T12:35:12.132+0000] {standard_task_runner.py:83} INFO - Job 13: Subtask send_alert
[2025-03-20T12:35:12.221+0000] {task_command.py:389} INFO - Running <TaskInstance: tech_sentiment_pipeline.send_alert scheduled__2025-03-20T12:20:00+00:00 [running]> on host 9f648da9db19
[2025-03-20T12:35:12.307+0000] {taskinstance.py:1513} INFO - Exporting the following env vars:
AIRFLOW_CTX_DAG_OWNER=***
AIRFLOW_CTX_DAG_ID=tech_sentiment_pipeline
AIRFLOW_CTX_TASK_ID=send_alert
AIRFLOW_CTX_EXECUTION_DATE=2025-03-20T12:20:00+00:00
AIRFLOW_CTX_TRY_NUMBER=2
AIRFLOW_CTX_DAG_RUN_ID=scheduled__2025-03-20T12:20:00+00:00
[2025-03-20T12:35:12.320+0000] {logging_mixin.py:137} WARNING - /home/***/.local/lib/python3.7/site-packages/***/utils/email.py:120 RemovedInAirflow3Warning: Fetching SMTP credentials from configuration variables will be deprecated in a future release. Please set credentials using a connection instead.
[2025-03-20T12:35:12.320+0000] {email.py:229} INFO - Email alerting: attempt 1
[2025-03-20T12:35:12.324+0000] {taskinstance.py:1772} ERROR - Task failed with exception
Traceback (most recent call last):
  File "/home/airflow/.local/lib/python3.7/site-packages/airflow/operators/email.py", line 87, in execute
    custom_headers=self.custom_headers,
  File "/home/airflow/.local/lib/python3.7/site-packages/airflow/utils/email.py", line 72, in send_email
    **kwargs,
  File "/home/airflow/.local/lib/python3.7/site-packages/airflow/utils/email.py", line 120, in send_email_smtp
    send_mime_email(e_from=mail_from, e_to=recipients, mime_msg=msg, conn_id=conn_id, dryrun=dryrun)
  File "/home/airflow/.local/lib/python3.7/site-packages/airflow/utils/email.py", line 231, in send_mime_email
    smtp_conn = _get_smtp_connection(smtp_host, smtp_port, smtp_timeout, smtp_ssl)
  File "/home/airflow/.local/lib/python3.7/site-packages/airflow/utils/email.py", line 265, in _get_smtp_connection
    else smtplib.SMTP(host=host, port=port, timeout=timeout)
  File "/usr/local/lib/python3.7/smtplib.py", line 251, in __init__
    (code, msg) = self.connect(host, port)
  File "/usr/local/lib/python3.7/smtplib.py", line 336, in connect
    self.sock = self._get_socket(host, port, self.timeout)
  File "/usr/local/lib/python3.7/smtplib.py", line 307, in _get_socket
    self.source_address)
  File "/usr/local/lib/python3.7/socket.py", line 728, in create_connection
    raise err
  File "/usr/local/lib/python3.7/socket.py", line 716, in create_connection
    sock.connect(sa)
OSError: [Errno 101] Network is unreachable
[2025-03-20T12:35:12.334+0000] {taskinstance.py:1327} INFO - Marking task as FAILED. dag_id=tech_sentiment_pipeline, task_id=send_alert, execution_date=20250320T122000, start_date=20250320T123512, end_date=20250320T123512
[2025-03-20T12:35:12.355+0000] {standard_task_runner.py:105} ERROR - Failed to execute job 13 for task send_alert ([Errno 101] Network is unreachable; 339)
[2025-03-20T12:35:12.381+0000] {local_task_job.py:159} INFO - Task exited with return code 1
[2025-03-20T12:35:12.401+0000] {taskinstance.py:2582} INFO - 0 downstream tasks scheduled from follow-on schedule check
